[2022-10-10 19:13:36,881] {taskinstance.py:1032} INFO - Dependencies all met for <TaskInstance: DesafioAirflow.export_final_output scheduled__2022-10-09T22:13:29.000546+00:00 [queued]>
[2022-10-10 19:13:36,885] {taskinstance.py:1032} INFO - Dependencies all met for <TaskInstance: DesafioAirflow.export_final_output scheduled__2022-10-09T22:13:29.000546+00:00 [queued]>
[2022-10-10 19:13:36,885] {taskinstance.py:1238} INFO - 
--------------------------------------------------------------------------------
[2022-10-10 19:13:36,885] {taskinstance.py:1239} INFO - Starting attempt 1 of 2
[2022-10-10 19:13:36,885] {taskinstance.py:1240} INFO - 
--------------------------------------------------------------------------------
[2022-10-10 19:13:36,896] {taskinstance.py:1259} INFO - Executing <Task(PythonOperator): export_final_output> on 2022-10-09 22:13:29.000546+00:00
[2022-10-10 19:13:36,899] {standard_task_runner.py:52} INFO - Started process 23383 to run task
[2022-10-10 19:13:36,901] {standard_task_runner.py:76} INFO - Running: ['airflow', 'tasks', 'run', 'DesafioAirflow', 'export_final_output', 'scheduled__2022-10-09T22:13:29.000546+00:00', '--job-id', '9', '--raw', '--subdir', 'DAGS_FOLDER/example_desafio.py', '--cfg-path', '/tmp/tmp9du54mfc', '--error-file', '/tmp/tmpyog8aqz5']
[2022-10-10 19:13:36,901] {standard_task_runner.py:77} INFO - Job 9: Subtask export_final_output
[2022-10-10 19:13:36,940] {logging_mixin.py:109} INFO - Running <TaskInstance: DesafioAirflow.export_final_output scheduled__2022-10-09T22:13:29.000546+00:00 [running]> on host LAPTOP-P5116HF5.localdomain
[2022-10-10 19:13:36,976] {taskinstance.py:1424} INFO - Exporting the following env vars:
AIRFLOW_CTX_DAG_EMAIL=airflow@example.com
AIRFLOW_CTX_DAG_OWNER=airflow
AIRFLOW_CTX_DAG_ID=DesafioAirflow
AIRFLOW_CTX_TASK_ID=export_final_output
AIRFLOW_CTX_EXECUTION_DATE=2022-10-09T22:13:29.000546+00:00
AIRFLOW_CTX_DAG_RUN_ID=scheduled__2022-10-09T22:13:29.000546+00:00
[2022-10-10 19:13:36,979] {taskinstance.py:1700} ERROR - Task failed with exception
Traceback (most recent call last):
  File "/home/mayara/airflow_tooltorial/venv/lib/python3.8/site-packages/airflow/models/taskinstance.py", line 1329, in _run_raw_task
    self._execute_task_with_callbacks(context)
  File "/home/mayara/airflow_tooltorial/venv/lib/python3.8/site-packages/airflow/models/taskinstance.py", line 1455, in _execute_task_with_callbacks
    result = self._execute_task(context, self.task)
  File "/home/mayara/airflow_tooltorial/venv/lib/python3.8/site-packages/airflow/models/taskinstance.py", line 1511, in _execute_task
    result = execute_callable(context=context)
  File "/home/mayara/airflow_tooltorial/venv/lib/python3.8/site-packages/airflow/operators/python.py", line 174, in execute
    return_value = self.execute_callable()
  File "/home/mayara/airflow_tooltorial/venv/lib/python3.8/site-packages/airflow/operators/python.py", line 185, in execute_callable
    return self.python_callable(*self.op_args, **self.op_kwargs)
  File "/home/mayara/airflow_tooltorial/airflow-data/dags/example_desafio.py", line 32, in export_final_answer
    my_email = Variable.get("my_email")
  File "/home/mayara/airflow_tooltorial/venv/lib/python3.8/site-packages/airflow/models/variable.py", line 140, in get
    raise KeyError(f'Variable {key} does not exist')
KeyError: 'Variable my_email does not exist'
[2022-10-10 19:13:36,984] {taskinstance.py:1267} INFO - Marking task as UP_FOR_RETRY. dag_id=DesafioAirflow, task_id=export_final_output, execution_date=20221009T221329, start_date=20221010T221336, end_date=20221010T221336
[2022-10-10 19:13:36,992] {logging_mixin.py:109} WARNING - /home/mayara/airflow_tooltorial/venv/lib/python3.8/site-packages/airflow/utils/context.py:152 AirflowContextDeprecationWarning: Accessing 'execution_date' from the template is deprecated and will be removed in a future version. Please use 'data_interval_start' or 'logical_date' instead.
[2022-10-10 19:13:36,992] {logging_mixin.py:109} WARNING - /home/mayara/airflow_tooltorial/venv/lib/python3.8/site-packages/airflow/utils/context.py:152 AirflowContextDeprecationWarning: Accessing 'next_ds' from the template is deprecated and will be removed in a future version. Please use '{{ data_interval_end | ds }}' instead.
[2022-10-10 19:13:36,993] {logging_mixin.py:109} WARNING - /home/mayara/airflow_tooltorial/venv/lib/python3.8/site-packages/airflow/utils/context.py:152 AirflowContextDeprecationWarning: Accessing 'next_ds_nodash' from the template is deprecated and will be removed in a future version. Please use '{{ data_interval_end | ds_nodash }}' instead.
[2022-10-10 19:13:36,994] {logging_mixin.py:109} WARNING - /home/mayara/airflow_tooltorial/venv/lib/python3.8/site-packages/airflow/utils/context.py:152 AirflowContextDeprecationWarning: Accessing 'next_execution_date' from the template is deprecated and will be removed in a future version. Please use 'data_interval_end' instead.
[2022-10-10 19:13:36,994] {logging_mixin.py:109} WARNING - /home/mayara/airflow_tooltorial/venv/lib/python3.8/site-packages/airflow/utils/context.py:152 AirflowContextDeprecationWarning: Accessing 'prev_ds' from the template is deprecated and will be removed in a future version.
[2022-10-10 19:13:36,995] {logging_mixin.py:109} WARNING - /home/mayara/airflow_tooltorial/venv/lib/python3.8/site-packages/airflow/utils/context.py:152 AirflowContextDeprecationWarning: Accessing 'prev_ds_nodash' from the template is deprecated and will be removed in a future version.
[2022-10-10 19:13:36,995] {logging_mixin.py:109} WARNING - /home/mayara/airflow_tooltorial/venv/lib/python3.8/site-packages/airflow/utils/context.py:152 AirflowContextDeprecationWarning: Accessing 'prev_execution_date' from the template is deprecated and will be removed in a future version.
[2022-10-10 19:13:36,996] {logging_mixin.py:109} WARNING - /home/mayara/airflow_tooltorial/venv/lib/python3.8/site-packages/airflow/utils/context.py:152 AirflowContextDeprecationWarning: Accessing 'prev_execution_date_success' from the template is deprecated and will be removed in a future version. Please use 'prev_data_interval_start_success' instead.
[2022-10-10 19:13:36,996] {logging_mixin.py:109} WARNING - /home/mayara/airflow_tooltorial/venv/lib/python3.8/site-packages/airflow/utils/context.py:152 AirflowContextDeprecationWarning: Accessing 'tomorrow_ds' from the template is deprecated and will be removed in a future version.
[2022-10-10 19:13:36,997] {logging_mixin.py:109} WARNING - /home/mayara/airflow_tooltorial/venv/lib/python3.8/site-packages/airflow/utils/context.py:152 AirflowContextDeprecationWarning: Accessing 'tomorrow_ds_nodash' from the template is deprecated and will be removed in a future version.
[2022-10-10 19:13:36,997] {logging_mixin.py:109} WARNING - /home/mayara/airflow_tooltorial/venv/lib/python3.8/site-packages/airflow/utils/context.py:152 AirflowContextDeprecationWarning: Accessing 'yesterday_ds' from the template is deprecated and will be removed in a future version.
[2022-10-10 19:13:36,998] {logging_mixin.py:109} WARNING - /home/mayara/airflow_tooltorial/venv/lib/python3.8/site-packages/airflow/utils/context.py:152 AirflowContextDeprecationWarning: Accessing 'yesterday_ds_nodash' from the template is deprecated and will be removed in a future version.
[2022-10-10 19:13:37,005] {logging_mixin.py:109} WARNING - /home/mayara/airflow_tooltorial/venv/lib/python3.8/site-packages/airflow/utils/email.py:102 PendingDeprecationWarning: Fetching SMTP credentials from configuration variables will be deprecated in a future release. Please set credentials using a connection instead.
[2022-10-10 19:13:37,005] {configuration.py:381} WARNING - section/key [smtp/smtp_user] not found in config
[2022-10-10 19:13:37,005] {email.py:208} INFO - Email alerting: attempt 1
[2022-10-10 19:13:37,008] {configuration.py:381} WARNING - section/key [smtp/smtp_user] not found in config
[2022-10-10 19:13:37,008] {email.py:208} INFO - Email alerting: attempt 1
[2022-10-10 19:13:37,009] {taskinstance.py:1751} ERROR - Failed to send email to: ['airflow@example.com']
Traceback (most recent call last):
  File "/home/mayara/airflow_tooltorial/venv/lib/python3.8/site-packages/airflow/models/taskinstance.py", line 1329, in _run_raw_task
    self._execute_task_with_callbacks(context)
  File "/home/mayara/airflow_tooltorial/venv/lib/python3.8/site-packages/airflow/models/taskinstance.py", line 1455, in _execute_task_with_callbacks
    result = self._execute_task(context, self.task)
  File "/home/mayara/airflow_tooltorial/venv/lib/python3.8/site-packages/airflow/models/taskinstance.py", line 1511, in _execute_task
    result = execute_callable(context=context)
  File "/home/mayara/airflow_tooltorial/venv/lib/python3.8/site-packages/airflow/operators/python.py", line 174, in execute
    return_value = self.execute_callable()
  File "/home/mayara/airflow_tooltorial/venv/lib/python3.8/site-packages/airflow/operators/python.py", line 185, in execute_callable
    return self.python_callable(*self.op_args, **self.op_kwargs)
  File "/home/mayara/airflow_tooltorial/airflow-data/dags/example_desafio.py", line 32, in export_final_answer
    my_email = Variable.get("my_email")
  File "/home/mayara/airflow_tooltorial/venv/lib/python3.8/site-packages/airflow/models/variable.py", line 140, in get
    raise KeyError(f'Variable {key} does not exist')
KeyError: 'Variable my_email does not exist'

During handling of the above exception, another exception occurred:

Traceback (most recent call last):
  File "/home/mayara/airflow_tooltorial/venv/lib/python3.8/site-packages/airflow/models/taskinstance.py", line 2093, in email_alert
    send_email(self.task.email, subject, html_content)
  File "/home/mayara/airflow_tooltorial/venv/lib/python3.8/site-packages/airflow/utils/email.py", line 55, in send_email
    return backend(
  File "/home/mayara/airflow_tooltorial/venv/lib/python3.8/site-packages/airflow/utils/email.py", line 102, in send_email_smtp
    send_mime_email(e_from=smtp_mail_from, e_to=recipients, mime_msg=msg, conn_id=conn_id, dryrun=dryrun)
  File "/home/mayara/airflow_tooltorial/venv/lib/python3.8/site-packages/airflow/utils/email.py", line 210, in send_mime_email
    conn = _get_smtp_connection(smtp_host, smtp_port, smtp_timeout, smtp_ssl)
  File "/home/mayara/airflow_tooltorial/venv/lib/python3.8/site-packages/airflow/utils/email.py", line 244, in _get_smtp_connection
    else smtplib.SMTP(host=host, port=port, timeout=timeout)
  File "/usr/lib/python3.8/smtplib.py", line 255, in __init__
    (code, msg) = self.connect(host, port)
  File "/usr/lib/python3.8/smtplib.py", line 339, in connect
    self.sock = self._get_socket(host, port, self.timeout)
  File "/usr/lib/python3.8/smtplib.py", line 310, in _get_socket
    return socket.create_connection((host, port), timeout,
  File "/usr/lib/python3.8/socket.py", line 808, in create_connection
    raise err
  File "/usr/lib/python3.8/socket.py", line 796, in create_connection
    sock.connect(sa)
ConnectionRefusedError: [Errno 111] Connection refused

During handling of the above exception, another exception occurred:

Traceback (most recent call last):
  File "/home/mayara/airflow_tooltorial/venv/lib/python3.8/site-packages/airflow/models/taskinstance.py", line 1749, in handle_failure
    self.email_alert(error)
  File "/home/mayara/airflow_tooltorial/venv/lib/python3.8/site-packages/airflow/models/taskinstance.py", line 2095, in email_alert
    send_email(self.task.email, subject, html_content_err)
  File "/home/mayara/airflow_tooltorial/venv/lib/python3.8/site-packages/airflow/utils/email.py", line 55, in send_email
    return backend(
  File "/home/mayara/airflow_tooltorial/venv/lib/python3.8/site-packages/airflow/utils/email.py", line 102, in send_email_smtp
    send_mime_email(e_from=smtp_mail_from, e_to=recipients, mime_msg=msg, conn_id=conn_id, dryrun=dryrun)
  File "/home/mayara/airflow_tooltorial/venv/lib/python3.8/site-packages/airflow/utils/email.py", line 210, in send_mime_email
    conn = _get_smtp_connection(smtp_host, smtp_port, smtp_timeout, smtp_ssl)
  File "/home/mayara/airflow_tooltorial/venv/lib/python3.8/site-packages/airflow/utils/email.py", line 244, in _get_smtp_connection
    else smtplib.SMTP(host=host, port=port, timeout=timeout)
  File "/usr/lib/python3.8/smtplib.py", line 255, in __init__
    (code, msg) = self.connect(host, port)
  File "/usr/lib/python3.8/smtplib.py", line 339, in connect
    self.sock = self._get_socket(host, port, self.timeout)
  File "/usr/lib/python3.8/smtplib.py", line 310, in _get_socket
    return socket.create_connection((host, port), timeout,
  File "/usr/lib/python3.8/socket.py", line 808, in create_connection
    raise err
  File "/usr/lib/python3.8/socket.py", line 796, in create_connection
    sock.connect(sa)
ConnectionRefusedError: [Errno 111] Connection refused
[2022-10-10 19:13:37,042] {standard_task_runner.py:89} ERROR - Failed to execute job 9 for task export_final_output
Traceback (most recent call last):
  File "/home/mayara/airflow_tooltorial/venv/lib/python3.8/site-packages/airflow/task/task_runner/standard_task_runner.py", line 85, in _start_by_fork
    args.func(args, dag=self.dag)
  File "/home/mayara/airflow_tooltorial/venv/lib/python3.8/site-packages/airflow/cli/cli_parser.py", line 48, in command
    return func(*args, **kwargs)
  File "/home/mayara/airflow_tooltorial/venv/lib/python3.8/site-packages/airflow/utils/cli.py", line 92, in wrapper
    return f(*args, **kwargs)
  File "/home/mayara/airflow_tooltorial/venv/lib/python3.8/site-packages/airflow/cli/commands/task_command.py", line 298, in task_run
    _run_task_by_selected_method(args, dag, ti)
  File "/home/mayara/airflow_tooltorial/venv/lib/python3.8/site-packages/airflow/cli/commands/task_command.py", line 107, in _run_task_by_selected_method
    _run_raw_task(args, ti)
  File "/home/mayara/airflow_tooltorial/venv/lib/python3.8/site-packages/airflow/cli/commands/task_command.py", line 180, in _run_raw_task
    ti._run_raw_task(
  File "/home/mayara/airflow_tooltorial/venv/lib/python3.8/site-packages/airflow/utils/session.py", line 70, in wrapper
    return func(*args, session=session, **kwargs)
  File "/home/mayara/airflow_tooltorial/venv/lib/python3.8/site-packages/airflow/models/taskinstance.py", line 1329, in _run_raw_task
    self._execute_task_with_callbacks(context)
  File "/home/mayara/airflow_tooltorial/venv/lib/python3.8/site-packages/airflow/models/taskinstance.py", line 1455, in _execute_task_with_callbacks
    result = self._execute_task(context, self.task)
  File "/home/mayara/airflow_tooltorial/venv/lib/python3.8/site-packages/airflow/models/taskinstance.py", line 1511, in _execute_task
    result = execute_callable(context=context)
  File "/home/mayara/airflow_tooltorial/venv/lib/python3.8/site-packages/airflow/operators/python.py", line 174, in execute
    return_value = self.execute_callable()
  File "/home/mayara/airflow_tooltorial/venv/lib/python3.8/site-packages/airflow/operators/python.py", line 185, in execute_callable
    return self.python_callable(*self.op_args, **self.op_kwargs)
  File "/home/mayara/airflow_tooltorial/airflow-data/dags/example_desafio.py", line 32, in export_final_answer
    my_email = Variable.get("my_email")
  File "/home/mayara/airflow_tooltorial/venv/lib/python3.8/site-packages/airflow/models/variable.py", line 140, in get
    raise KeyError(f'Variable {key} does not exist')
KeyError: 'Variable my_email does not exist'
[2022-10-10 19:13:37,074] {local_task_job.py:154} INFO - Task exited with return code 1
[2022-10-10 19:13:37,085] {local_task_job.py:264} INFO - 0 downstream tasks scheduled from follow-on schedule check
